downloaded
downloaded
downloaded
downloaded
downloaded
downloaded
downloaded
downloaded
downloaded
downloaded
downloaded
downloaded
downloaded
downloaded
downloaded
downloaded
downloaded
downloaded
downloaded
downloaded
downloaded
downloaded
downloaded
downloaded
downloaded
downloaded
downloaded
downloaded
downloaded
downloaded
downloaded
downloaded
downloaded
downloaded
downloaded
downloaded
downloaded
downloaded
downloaded
downloaded
downloaded
downloaded
downloaded
downloaded
downloaded
downloaded
downloaded
downloaded
downloaded
downloaded
Traceback (most recent call last):
  File "/home/targets/anaconda3/lib/python3.7/site-packages/urllib3/connection.py", line 157, in _new_conn
    (self._dns_host, self.port), self.timeout, **extra_kw
  File "/home/targets/anaconda3/lib/python3.7/site-packages/urllib3/util/connection.py", line 84, in create_connection
    raise err
  File "/home/targets/anaconda3/lib/python3.7/site-packages/urllib3/util/connection.py", line 74, in create_connection
    sock.connect(sa)
OSError: [Errno 101] Network is unreachable

During handling of the above exception, another exception occurred:

Traceback (most recent call last):
  File "/home/targets/anaconda3/lib/python3.7/site-packages/urllib3/connectionpool.py", line 672, in urlopen
    chunked=chunked,
  File "/home/targets/anaconda3/lib/python3.7/site-packages/urllib3/connectionpool.py", line 376, in _make_request
    self._validate_conn(conn)
  File "/home/targets/anaconda3/lib/python3.7/site-packages/urllib3/connectionpool.py", line 994, in _validate_conn
    conn.connect()
  File "/home/targets/anaconda3/lib/python3.7/site-packages/urllib3/connection.py", line 300, in connect
    conn = self._new_conn()
  File "/home/targets/anaconda3/lib/python3.7/site-packages/urllib3/connection.py", line 169, in _new_conn
    self, "Failed to establish a new connection: %s" % e
urllib3.exceptions.NewConnectionError: <urllib3.connection.VerifiedHTTPSConnection object at 0x7f5964aacf10>: Failed to establish a new connection: [Errno 101] Network is unreachable

During handling of the above exception, another exception occurred:

Traceback (most recent call last):
  File "/home/targets/anaconda3/lib/python3.7/site-packages/requests/adapters.py", line 499, in send
    timeout=timeout,
  File "/home/targets/anaconda3/lib/python3.7/site-packages/urllib3/connectionpool.py", line 720, in urlopen
    method, url, error=e, _pool=self, _stacktrace=sys.exc_info()[2]
  File "/home/targets/anaconda3/lib/python3.7/site-packages/urllib3/util/retry.py", line 436, in increment
    raise MaxRetryError(_pool, url, error or ResponseError(cause))
urllib3.exceptions.MaxRetryError: HTTPSConnectionPool(host='www.cbc.gov.tw', port=443): Max retries exceeded with url: /public/data/OpenData/%E5%A4%96%E5%8C%AF%E5%B1%80/FTDOpenData015.csv (Caused by NewConnectionError('<urllib3.connection.VerifiedHTTPSConnection object at 0x7f5964aacf10>: Failed to establish a new connection: [Errno 101] Network is unreachable'))

During handling of the above exception, another exception occurred:

Traceback (most recent call last):
  File "/home/targets/autocommit/EXCEL_AutoUpdate/csv_download.py", line 12, in <module>
    req = requests.get(csv_url)
  File "/home/targets/anaconda3/lib/python3.7/site-packages/requests/api.py", line 73, in get
    return request("get", url, params=params, **kwargs)
  File "/home/targets/anaconda3/lib/python3.7/site-packages/requests/api.py", line 59, in request
    return session.request(method=method, url=url, **kwargs)
  File "/home/targets/anaconda3/lib/python3.7/site-packages/requests/sessions.py", line 587, in request
    resp = self.send(prep, **send_kwargs)
  File "/home/targets/anaconda3/lib/python3.7/site-packages/requests/sessions.py", line 701, in send
    r = adapter.send(request, **kwargs)
  File "/home/targets/anaconda3/lib/python3.7/site-packages/requests/adapters.py", line 565, in send
    raise ConnectionError(e, request=request)
requests.exceptions.ConnectionError: HTTPSConnectionPool(host='www.cbc.gov.tw', port=443): Max retries exceeded with url: /public/data/OpenData/%E5%A4%96%E5%8C%AF%E5%B1%80/FTDOpenData015.csv (Caused by NewConnectionError('<urllib3.connection.VerifiedHTTPSConnection object at 0x7f5964aacf10>: Failed to establish a new connection: [Errno 101] Network is unreachable'))
downloaded
downloaded
downloaded
downloaded
downloaded
downloaded
downloaded
downloaded
downloaded
downloaded
downloaded
downloaded
downloaded
downloaded
downloaded
downloaded
downloaded
downloaded
downloaded
downloaded
downloaded
downloaded
downloaded
downloaded
downloaded
downloaded
downloaded
downloaded
downloaded
downloaded
downloaded
downloaded
downloaded
downloaded
downloaded
downloaded
downloaded
downloaded
downloaded
downloaded
downloaded
downloaded
downloaded
downloaded
downloaded
downloaded
downloaded
downloaded
downloaded
downloaded
downloaded
downloaded
downloaded
downloaded
downloaded
downloaded
downloaded
downloaded
downloaded
downloaded
downloaded
downloaded
downloaded
downloaded
downloaded
downloaded
downloaded
downloaded
downloaded
downloaded
downloaded
downloaded
downloaded
downloaded
downloaded
downloaded
downloaded
downloaded
downloaded
downloaded
downloaded
downloaded
downloaded
downloaded
downloaded
downloaded
downloaded
downloaded
downloaded
downloaded
downloaded
downloaded
downloaded
downloaded
downloaded
downloaded
downloaded
downloaded
downloaded
downloaded
downloaded
downloaded
downloaded
downloaded
downloaded
downloaded
downloaded
downloaded
downloaded
downloaded
downloaded
downloaded
downloaded
downloaded
downloaded
downloaded
downloaded
downloaded
downloaded
downloaded
downloaded
downloaded
downloaded
downloaded
downloaded
downloaded
downloaded
downloaded
downloaded
downloaded
downloaded
downloaded
downloaded
downloaded
downloaded
downloaded
downloaded
downloaded
downloaded
downloaded
downloaded
downloaded
downloaded
downloaded
downloaded
downloaded
downloaded
downloaded
downloaded
downloaded
downloaded
downloaded
downloaded
downloaded
downloaded
downloaded
downloaded
downloaded
downloaded
downloaded
downloaded
downloaded
downloaded
downloaded
downloaded
downloaded
downloaded
downloaded
downloaded
downloaded
downloaded
downloaded
downloaded
downloaded
downloaded
downloaded
downloaded
downloaded
downloaded
downloaded
downloaded
downloaded
downloaded
downloaded
downloaded
downloaded
